Workbook

Sheet TABLA_1_INV
A1: CODIGO | B1: NOMBRE DEL PRODUCTO | C1: NOMBRE GENERICO | D1: TOTAL INVENT | E1: UNIDAD DE MEDIDA | F1: UBICACIÓN | G1: CANT ADQUIRIDA | H1: PROVEEDOR PRINCIPAL | I1: PROVEEDOR SUPLENTE | J1: PROVEEDOR 3 | K1: PROVEEDOR 4
A2: A00000001 | B2: HIDROXIDO DE SODIO EN ESCAMAS_SACO X 25KG - 99% | C2: SODA EN ESCAMAS | D2: 450 | E2: KG | F2: PLANTA PTARND | H2: CIACOMEQ SAS | I2: FERGQUIM SAS | J2: DISTRIBUIDORA ALIADOS | K2: ASERING SAS
A3: A00000002 | B3: HIDROXIDO DE SODIO LIQUIDA_TAMBOR X 250KG - 50% | C3: SODA LIQUIDA | D3: 0 | E3: KG | F3: N/A | H3: CIACOMEQ SAS | I3: DISTRIBUIDORA ALIADOS | J3: FERGQUIM SAS
A4: A00000003 | B4: HIPOCLORITO DE SODIO LIQUIDO_TAMBOR X 250KG - 15% | C4: HIPOCLORITO DE SODIO | D4: 410 | E4: KG | F4: PLANTA PTARND | H4: CIACOMEQ SAS | I4: DISTRIBUIDORA ALIADOS | J4: FERGQUIM SAS
A5: A00000004 | B5: HIPOCLORITO DE SODIO LIQUIDO_GARRAFA X 24KG - 15% | C5: HIPOCLORITO DE SODIO | D5: 0 | E5: KG | F5: N/A | H5: CIACOMEQ SAS | I5: DISTRIBUIDORA ALIADOS | J5: FERGQUIM SAS
A6: A00000005 | B6: AGUA DESMINERALIZADA_GARRAFA X 20L | C6: AGUA DESMINERALIZADA | D6: 0 | E6: KG | F6: N/A | H6: CIACOMEQ SAS | I6: PROQUIMICAS JG | J6: DISTRIBUIDORA ALIADOS | K6: FERGQUIM SAS
A7: A00000006 | B7: SILICONA ANTIESPUMANTE LIQUIDO_GARRAFA X 20L | C7: ANTIESPUMANTE | D7: 28 | E7: L | F7: BODEGA PTARND | H7: CIACOMEQ SAS | I7: DISTRIBUIDORA ALIADOS | J7: MAR QUIMICOS SAS
A8: A00000007 | B8: CLORURO FERRICO LIQUIDO_GARRAFA X 30KG - 42% | C8: CLORURO FERRICO | D8: 510 | E8: KG | F8: PLANTA PTARND | H8: CIACOMEQ SAS
A9: A00000008 | B9: CLORURO FERRICO LIQUIDO_TAMBOR X 250KG - 42% | C9: CLORURO FERRICO | D9: 0 | E9: KG | F9: N/A | H9: FERGQUIM SAS | I9: DISTRIBUIDORA ALIADOS
A10: A00000009 | B10: POLIMERO ANIONICO SOLIDO_ASPRE FLOC AN 315_BOLSA X 1KG - 99% | C10: PAM ANIONICO | D10: 10 | E10: KG | F10: BODEGA PTARND | H10: CIACOMEQ SAS | I10: DISTRIBUIDORA ALIADOS | J10: CASA QUIMICOS SAS
A11: A00000010 | B11: PEROXIDO DE HIDROGENO LIQUIDO_GARRAFA X 30KG - 50% | C11: PEROXIDO | D11: 30 | E11: KG | F11: BODEGA PTARND | H11: FERGQUIM SAS | I11: DISTRIBUIDORA ALIADOS
A12: A00000011 | B12: ACIDO CITRICO SOLIDO_BOLSA X 1KG - 99% | C12: ACIDO CITRICO | D12: 14 | E12: KG | F12: BODEGA PTARND | H12: CIACOMEQ SAS | I12: PROQUIMICAS JG | J12: DISTRIBUIDORA ALIADOS | K12: FERGQUIM SAS
A13: A00000012 | B13: BISULFITO DE SODIO_SACO X 25KG - 99% | C13: BISULFITO | D13: 0 | E13: KG | F13: N/A
A14: A00000013 | B14: CUBETA TEST DQO X 25 - RANGO BAJO (0 -150 mg/l) - HI93754A-25 | C14: VIALES DQO BAJO | D14: 45 | E14: UND | F14: LABORATORIO PTARND | H14: HANNA INSTRUMENTS COLOMBIA
A15: A00000014 | B15: CUBETA TEST DQO X 25 - RANGO MEDIO (0 -1500 mg/l) - HI93754B-25 | C15: VIALES DQO MEDIO | D15: 0 | E15: UND | F15: LABORATORIO PTARND | H15: HANNA INSTRUMENTS COLOMBIA
A16: A00000015 | B16: CUBETA TEST DQO X 25 - RANGO ALTO (0 -15000 mg/l) - HI93754C-25 | C16: VIALES DQO ALTO | D16: 19 | E16: UND | F16: LABORATORIO PTARND | H16: HANNA INSTRUMENTS COLOMBIA
A17: A00000016 | B17: TEST KIT CLORUROS - HI3815 | C17: TEST CLORUROS | D17: 1 | E17: UND | F17: LABORATORIO PTARND | H17: HANNA INSTRUMENTS COLOMBIA
A18: A00000017 | B18: REACTIVO COBRE RANGO ALTO - HI93702-01 | C18: REACTIVO COBRE | D18: 81 | E18: UND | F18: LABORATORIO PTARND | H18: HANNA INSTRUMENTS COLOMBIA
A19: A00000018 | B19: REACTIVO HIERRO RANGO ALTO - HI93721-01 | C19: REACTIVO HIERRO | D19: 71 | E19: UND | F19: LABORATORIO PTARND | H19: HANNA INSTRUMENTS COLOMBIA
A20: A00000019 | B20: REACTIVO CLORO TOTAL - HI93711-01 | C20: REACTIVO CLORO TOTAL | D20: 71 | E20: UND | F20: LABORATORIO PTARND | H20: HANNA INSTRUMENTS COLOMBIA
A21: A00000020 | B21: REACTIVO CROMO 6 RANGO ALTO - HI93723-01 | C21: REACTIVO CROMO | D21: 21 | E21: UND | F21: LABORATORIO PTARND | H21: HANNA INSTRUMENTS COLOMBIA
A22: A00000021 | B22: REACTIVO SULFATO - HI93751-01 | C22: REACTIVO SULFATO | D22: 80 | E22: UND | F22: LABORATORIO PTARND | H22: HANNA INSTRUMENTS COLOMBIA
A23: A00000022 | B23: REACTIVO CLORO LIBRE - HI93701-01 | C23: REACTIVO CLORO LIBRE | D23: 68 | E23: UND | F23: LABORATORIO PTARND | H23: HANNA INSTRUMENTS COLOMBIA
A24: A00000023 | B24: REACTIVO NIQUEL RANGO ALTO - HI93726-01 | C24: REACTIVO NIQUEL | D24: 82 | E24: UND | F24: LABORATORIO PTARND | H24: HANNA INSTRUMENTS COLOMBIA
A25: A00000024 | B25: TEST KIT FENOL - HI3864 | C25: TEST FENOL | D25: 22 | E25: UND | F25: LABORATORIO PTARND | H25: HANNA INSTRUMENTS COLOMBIA
... A44: A00000043 | B44: FILTRO MICROFILTRACION SWC-45-2025_50 MICRAS_ | C44: FILTRO DE PTAP | D44: 0 | E44: UND | F44: N/A | H44: FILTERBAG

Sheet TABLA_2_MASTER
A1: COD PROVEEDOR | B1: NOMBRE PROVEEDOR | C1: CONTACTO | D1: DIRECCION | E1: TELEFONO | F1: CELULAR | G1: WEB | H1: CORREO | I1: CODIGO MAT | J1: NOMBRE DEL PRODUCTO | K1: PRECIO | L1: UNIDAD MEDIDA | M1: UNIDAD DE COMPRA | N1: UNIDAD MIN DE COMPRA | O1: LEAD TIME DIAS | P1: MEDIO DE TRANSPORTE | Q1: REABASTECIMIENTO | R1: TERMINO DE PAGO | S1: TIEMPO DE CREDITO DIAS
A2: P0001 | B2: CIACOMEQ SAS | C2: CAROLINA CASTRO | D2: CARRERA 63 N 5A-85 BARRIO PRADERA - BOGOTA DC | E2: 601 290 0093 | F2: 317 4250689 | G2: Inicio - CIACOMEQ SAS | H2: servicioalcliente@ciacomeq.com | I2: A00000001 | J2: HIDROXIDO DE SODIO EN ESCAMAS_SACO X 25KG - 99% | K2: 4400 | L2: KG | M2: KG | N2: 25 | O2: 4 | P2: FURGON | Q2: 7 | R2: CONTADO | S2: 0
A3: P0001 | B3: CIACOMEQ SAS | C3: CAROLINA CASTRO | D3: CARRERA 63 N 5A-85 BARRIO PRADERA - BOGOTA DC | E3: 601 290 0093 | F3: 317 4250689 | G3: Inicio - CIACOMEQ SAS | H3: servicioalcliente@ciacomeq.com | I3: A00000002 | J3: HIDROXIDO DE SODIO LIQUIDA_TAMBOR X 250KG - 50% | K3: 2941 | L3: KG | M3: KG | N3: 250 | O3: 4 | P3: FURGON | Q3: 7 | R3: CONTADO | S3: 0
A4: P0001 | B4: CIACOMEQ SAS | C4: CAROLINA CASTRO | D4: CARRERA 63 N 5A-85 BARRIO PRADERA - BOGOTA DC | E4: 601 290 0093 | F4: 317 4250689 | G4: Inicio - CIACOMEQ SAS | H4: servicioalcliente@ciacomeq.com | I4: A00000003 | J4: HIPOCLORITO DE SODIO LIQUIDO_TAMBOR X 250KG - 15% | K4: 1446 | L4: KG | M4: KG | N4: 250 | O4: 4 | P4: FURGON | Q4: 7 | R4: CONTADO | S4: 0
A5: P0001 | B5: CIACOMEQ SAS | C5: CAROLINA CASTRO | D5: CARRERA 63 N 5A-85 BARRIO PRADERA - BOGOTA DC | E5: 601 290 0093 | F5: 317 4250689 | G5: Inicio - CIACOMEQ SAS | H5: servicioalcliente@ciacomeq.com | I5: A00000004 | J5: HIPOCLORITO DE SODIO LIQUIDO_GARRAFA X 24KG - 15% | K5: 2425 | L5: KG | M5: KG | N5: 24 | O5: 4 | P5: FURGON | Q5: 7 | R5: CONTADO | S5: 0
A6: P0001 | B6: CIACOMEQ SAS | C6: CAROLINA CASTRO | D6: CARRERA 63 N 5A-85 BARRIO PRADERA - BOGOTA DC | E6: 601 290 0093 | F6: 317 4250689 | G6: Inicio - CIACOMEQ SAS | H6: servicioalcliente@ciacomeq.com | I6: A00000005 | J6: AGUA DESMINERALIZADA_GARRAFA X 20L | K6: 1387.5 | L6: L | M6: L | N6: 20 | O6: 4 | P6: FURGON | Q6: 30 | R6: CONTADO | S6: 0
A7: P0001 | B7: CIACOMEQ SAS | C7: CAROLINA CASTRO | D7: CARRERA 63 N 5A-85 BARRIO PRADERA - BOGOTA DC | E7: 601 290 0093 | F7: 317 4250689 | G7: Inicio - CIACOMEQ SAS | H7: servicioalcliente@ciacomeq.com | I7: A00000006 | J7: SILICONA ANTIESPUMANTE LIQUIDO_GARRAFA X 20L | K7: 14348.7 | L7: L | M7: L | N7: 20 | O7: 4 | P7: FURGON | Q7: 7 | R7: CONTADO | S7: 0
A8: P0001 | B8: CIACOMEQ SAS | C8: CAROLINA CASTRO | D8: CARRERA 63 N 5A-85 BARRIO PRADERA - BOGOTA DC | E8: 601 290 0093 | F8: 317 4250689 | G8: Inicio - CIACOMEQ SAS | H8: servicioalcliente@ciacomeq.com | I8: A00000007 | J8: CLORURO FERRICO LIQUIDO_GARRAFA X 30KG - 42% | K8: 3333 | L8: KG | M8: KG | N8: 30 | O8: 4 | P8: FURGON | Q8: 7 | R8: CONTADO | S8: 0
A9: P0001 | B9: CIACOMEQ SAS | C9: CAROLINA CASTRO | D9: CARRERA 63 N 5A-85 BARRIO PRADERA - BOGOTA DC | E9: 601 290 0093 | F9: 317 4250689 | G9: Inicio - CIACOMEQ SAS | H9: servicioalcliente@ciacomeq.com | I9: A00000009 | J9: POLIMERO ANIONICO SOLIDO_ASPRE FLOC AN 315_BOLSA X 1KG - 99% | K9: 20000 | L9: KG | M9: KG | N9: 1 | O9: 4 | P9: FURGON | Q9: 7 | R9: CONTADO | S9: 0
A10: P0001 | B10: CIACOMEQ SAS | C10: CAROLINA CASTRO | D10: CARRERA 63 N 5A-85 BARRIO PRADERA - BOGOTA DC | E10: 601 290 0093 | F10: 317 4250689 | G10: Inicio - CIACOMEQ SAS | H10: servicioalcliente@ciacomeq.com | I10: A00000011 | J10: ACIDO CITRICO SOLIDO_BOLSA X 1KG - 99% | K10: 6723 | L10: KG | M10: KG | N10: 1 | O10: 4 | P10: FURGON | Q10: 7 | R10: CONTADO | S10: 0
A11: P0002 | B11: DISTRIBUIDORA ALIADOS | C11: TANIA RODRIGUEZ | D11: TRANSVERSAL 93 N 53-32_ENGATIVA_BOGOTA DC | E11: 601 414 1420 | F11: 3132085271 | G11: Nosotros | Distribuidora Aliados - 35 años de experiencia en productos químicos | H11: Ventas@distribuidoraaliados.com | I11: A00000001 | J11: HIDROXIDO DE SODIO EN ESCAMAS_SACO X 25KG - 99% | K11: 4450 | L11: KG | M11: KG | N11: 25 | O11: 2 | P11: FURGON | Q11: 7 | R11: CREDITO | S11: 8
A12: P0002 | B12: DISTRIBUIDORA ALIADOS | C12: TANIA RODRIGUEZ | D12: TRANSVERSAL 93 N 53-32_ENGATIVA_BOGOTA DC | E12: 601 414 1420 | F12: 3132085271 | G12: Nosotros | Distribuidora Aliados - 35 años de experiencia en productos químicos | H12: Ventas@distribuidoraaliados.com | I12: A00000002 | J12: HIDROXIDO DE SODIO LIQUIDA_TAMBOR X 250KG - 50% | K12: 2700 | L12: KG | M12: KG | N12: 250 | O12: 2 | P12: FURGON | Q12: 7 | R12: CREDITO | S12: 8
A13: P0002 | B13: DISTRIBUIDORA ALIADOS | C13: TANIA RODRIGUEZ | D13: TRANSVERSAL 93 N 53-32_ENGATIVA_BOGOTA DC | E13: 601 414 1420 | F13: 3132085271 | G13: Nosotros | Distribuidora Aliados - 35 años de experiencia en productos químicos | H13: Ventas@distribuidoraaliados.com | I13: A00000003 | J13: HIPOCLORITO DE SODIO LIQUIDO_TAMBOR X 250KG - 15% | K13: 2250 | L13: KG | M13: KG | N13: 250 | O13: 2 | P13: FURGON | Q13: 7 | R13: CREDITO | S13: 8
A14: P0002 | B14: DISTRIBUIDORA ALIADOS | C14: TANIA RODRIGUEZ | D14: TRANSVERSAL 93 N 53-32_ENGATIVA_BOGOTA DC | E14: 601 414 1420 | F14: 3132085271 | G14: Nosotros | Distribuidora Aliados - 35 años de experiencia en productos químicos | H14: Ventas@distribuidoraaliados.com | I14: A00000004 | J14: HIPOCLORITO DE SODIO LIQUIDO_GARRAFA X 24KG - 15% | K14: 2700 | L14: KG | M14: KG | N14: 24 | O14: 2 | P14: FURGON | Q14: 7 | R14: CREDITO | S14: 8
A15: P0002 | B15: DISTRIBUIDORA ALIADOS | C15: TANIA RODRIGUEZ | D15: TRANSVERSAL 93 N 53-32_ENGATIVA_BOGOTA DC | E15: 601 414 1420 | F15: 3132085271 | G15: Nosotros | Distribuidora Aliados - 35 años de experiencia en productos químicos | H15: Ventas@distribuidoraaliados.com | I15: A00000005 | J15: AGUA DESMINERALIZADA_GARRAFA X 20L | K15: 1750 | L15: L | M15: L | N15: 20 | O15: 2 | P15: FURGON | Q15: 30 | R15: CREDITO | S15: 8
A16: P0002 | B16: DISTRIBUIDORA ALIADOS | C16: TANIA RODRIGUEZ | D16: TRANSVERSAL 93 N 53-32_ENGATIVA_BOGOTA DC | E16: 601 414 1420 | F16: 3132085271 | G16: Nosotros | Distribuidora Aliados - 35 años de experiencia en productos químicos | H16: Ventas@distribuidoraaliados.com | I16: A00000006 | J16: SILICONA ANTIESPUMANTE LIQUIDO_GARRAFA X 20L | K16: =387400/20 -> 19370 | L16: L | M16: L | N16: 20 | O16: 2 | P16: FURGON | Q16: 7 | R16: CREDITO | S16: 8
A17: P0002 | B17: DISTRIBUIDORA ALIADOS | C17: TANIA RODRIGUEZ | D17: TRANSVERSAL 93 N 53-32_ENGATIVA_BOGOTA DC | E17: 601 414 1420 | F17: 3132085271 | G17: Nosotros | Distribuidora Aliados - 35 años de experiencia en productos químicos | H17: Ventas@distribuidoraaliados.com | I17: A00000008 | J17: CLORURO FERRICO LIQUIDO_TAMBOR X 250KG - 42% | K17: 2500 | L17: KG | M17: KG | N17: 250 | O17: 2 | P17: FURGON | Q17: 7 | R17: CREDITO | S17: 8
A18: P0002 | B18: DISTRIBUIDORA ALIADOS | C18: TANIA RODRIGUEZ | D18: TRANSVERSAL 93 N 53-32_ENGATIVA_BOGOTA DC | E18: 601 414 1420 | F18: 3132085271 | G18: Nosotros | Distribuidora Aliados - 35 años de experiencia en productos químicos | H18: Ventas@distribuidoraaliados.com | I18: A00000009 | J18: POLIMERO ANIONICO SOLIDO_ASPRE FLOC AN 315_BOLSA X 1KG - 99% | K18: 25000 | L18: KG | M18: KG | N18: 1 | O18: 2 | P18: FURGON | Q18: 7 | R18: CREDITO | S18: 8
A19: P0002 | B19: DISTRIBUIDORA ALIADOS | C19: TANIA RODRIGUEZ | D19: TRANSVERSAL 93 N 53-32_ENGATIVA_BOGOTA DC | E19: 601 414 1420 | F19: 3132085271 | G19: Nosotros | Distribuidora Aliados - 35 años de experiencia en productos químicos | H19: Ventas@distribuidoraaliados.com | I19: A00000010 | J19: PEROXIDO DE HIDROGENO LIQUIDO_GARRAFA X 30KG - 50% | K19: 4200 | L19: KG | M19: KG | N19: 30 | O19: 2 | P19: FURGON | Q19: 7 | R19: CREDITO | S19: 8
A20: P0002 | B20: DISTRIBUIDORA ALIADOS | C20: TANIA RODRIGUEZ | D20: TRANSVERSAL 93 N 53-32_ENGATIVA_BOGOTA DC | E20: 601 414 1420 | F20: 3132085271 | G20: Nosotros | Distribuidora Aliados - 35 años de experiencia en productos químicos | H20: Ventas@distribuidoraaliados.com | I20: A00000011 | J20: ACIDO CITRICO SOLIDO_BOLSA X 1KG - 99% | K20: 12000 | L20: KG | M20: KG | N20: 1 | O20: 2 | P20: FURGON | Q20: 7 | R20: CREDITO | S20: 8
A21: P0003 | B21: FERGQUIM SAS | C21: ANDRES MELDIVELSO | D21: PARQUE EMPRESARIAL DE OCCIDENTE, BODEGA 81 | E21: 601 8269712 | F21: 3507051990 | G21: Inicio - FergQuim | H21: comercial3@quimicosfergquim.com | I21: A00000001 | J21: HIDROXIDO DE SODIO EN ESCAMAS_SACO X 25KG - 99% | K21: 4800 | L21: KG | M21: KG | N21: 25 | O21: 5 | P21: FURGON | Q21: 7 | R21: CONTADO | S21: 0
A22: P0003 | B22: FERGQUIM SAS | C22: ANDRES MELDIVELSO | D22: PARQUE EMPRESARIAL DE OCCIDENTE, BODEGA 81 | E22: 601 8269712 | F22: 3507051990 | G22: Inicio - FergQuim | H22: comercial3@quimicosfergquim.com | I22: A00000002 | J22: HIDROXIDO DE SODIO LIQUIDA_TAMBOR X 250KG - 50% | K22: 2600 | L22: KG | M22: KG | N22: 250 | O22: 5 | P22: FURGON | Q22: 7 | R22: CONTADO | S22: 0
A23: P0003 | B23: FERGQUIM SAS | C23: ANDRES MELDIVELSO | D23: PARQUE EMPRESARIAL DE OCCIDENTE, BODEGA 81 | E23: 601 8269712 | F23: 3507051990 | G23: Inicio - FergQuim | H23: comercial3@quimicosfergquim.com | I23: A00000003 | J23: HIPOCLORITO DE SODIO LIQUIDO_TAMBOR X 250KG - 15% | K23: 1600 | L23: KG | M23: KG | N23: 250 | O23: 5 | P23: FURGON | Q23: 7 | R23: CONTADO | S23: 0
A24: P0003 | B24: FERGQUIM SAS | C24: ANDRES MELDIVELSO | D24: PARQUE EMPRESARIAL DE OCCIDENTE, BODEGA 81 | E24: 601 8269712 | F24: 3507051990 | G24: Inicio - FergQuim | H24: comercial3@quimicosfergquim.com | I24: A00000004 | J24: HIPOCLORITO DE SODIO LIQUIDO_GARRAFA X 24KG - 15% | K24: 1600 | L24: KG | M24: KG | N24: 24 | O24: 5 | P24: FURGON | Q24: 7 | R24: CONTADO | S24: 0
A25: P0003 | B25: FERGQUIM SAS | C25: ANDRES MELDIVELSO | D25: PARQUE EMPRESARIAL DE OCCIDENTE, BODEGA 81 | E25: 601 8269712 | F25: 3507051990 | G25: Inicio - FergQuim | H25: comercial3@quimicosfergquim.com | I25: A00000005 | J25: AGUA DESMINERALIZADA_GARRAFA X 20L | K25: 2920 | L25: L | M25: L | N25: 20 | O25: 5 | P25: FURGON | Q25: 30 | R25: CONTADO | S25: 0
A26: P0003 | B26: FERGQUIM SAS | C26: ANDRES MELDIVELSO | D26: PARQUE EMPRESARIAL DE OCCIDENTE, BODEGA 81 | E26: 601 8269712 | F26: 3507051990 | G26: Inicio - FergQuim | H26: comercial3@quimicosfergquim.com | I26: A00000008 | J26: CLORURO FERRICO LIQUIDO_TAMBOR X 250KG - 42% | K26: 2450 | L26: KG | M26: KG | N26: 250 | O26: 5 | P26: FURGON | Q26: 7 | R26: CONTADO | S26: 0
A27: P0003 | B27: FERGQUIM SAS | C27: ANDRES MELDIVELSO | D27: PARQUE EMPRESARIAL DE OCCIDENTE, BODEGA 81 | E27: 601 8269712 | F27: 3507051990 | G27: Inicio - FergQuim | H27: comercial3@quimicosfergquim.com | I27: A00000010 | J27: PEROXIDO DE HIDROGENO LIQUIDO_GARRAFA X 30KG - 50% | K27: 4200 | L27: KG | M27: KG | N27: 30 | O27: 5 | P27: FURGON | Q27: 7 | R27: CONTADO | S27: 0
A28: P0003 | B28: FERGQUIM SAS | C28: ANDRES MELDIVELSO | D28: PARQUE EMPRESARIAL DE OCCIDENTE, BODEGA 81 | E28: 601 8269712 | F28: 3507051990 | G28: Inicio - FergQuim | H28: comercial3@quimicosfergquim.com | I28: A00000011 | J28: ACIDO CITRICO SOLIDO_BOLSA X 1KG - 99% | K28: 2950 | L28: KG | M28: KG | N28: 1 | O28: 5 | P28: FURGON | Q28: 7 | R28: CONTADO | S28: 0
A29: P0004 | B29: PROQUIMICAS JG | C29: ALEJANDRO SARMIENTO | D29: Calle 73 # 20- 89 - BOGOTA DC | F29: 3202591565 | G29: PROQUIMICAS | I29: A00000005 | J29: AGUA DESMINERALIZADA_GARRAFA X 20L | L29: L | M29: L | N29: 20 | O29: 5 | P29: FURGON | Q29: 30 | R29: CONTADO | S29: 0
A30: P0004 | B30: PROQUIMICAS JG | C30: ALEJANDRO SARMIENTO | D30: Calle 73 # 20- 89 - BOGOTA DC | F30: 3202591565 | G30: PROQUIMICAS | I30: A00000011 | J30: ACIDO CITRICO SOLIDO_BOLSA X 1KG - 99% | L30: KG | M30: KG | N30: 1 | O30: 5 | P30: FURGON | Q30: 7 | R30: CONTADO | S30: 0
A31: P0005 | B31: ASERING SAS | C31: DANIELA CASTRO | D31: KM 2 VIA FUNZA SIBERIA – PARQUE INDUSTRIAL EL TREBOL | F31: 3505916780 | G31: Asering SAS | Asering S.A.S | H31: comercialaseringsas.co | I31: A00000001 | J31: HIDROXIDO DE SODIO EN ESCAMAS_SACO X 25KG - 99% | K31: 4300 | L31: KG | M31: KG | N31: 25 | O31: 2 | P31: FURGON | Q31: 7 | R31: CONTADO | S31: 0
A32: P0005 | B32: ASERING SAS | C32: DANIELA CASTRO | D32: KM 2 VIA FUNZA SIBERIA – PARQUE INDUSTRIAL EL TREBOL | F32: 3505916780 | G32: Asering SAS | Asering S.A.S | H32: comercialaseringsas.co | I32: A00000002 | J32: HIDROXIDO DE SODIO LIQUIDA_TAMBOR X 1000KG - 50% | K32: 4375 | L32: KG | M32: KG | N32: 1000 | O32: 2 | P32: FURGON | Q32: 7 | R32: CONTADO | S32: 0
A33: P0005 | B33: ASERING SAS | C33: DANIELA CASTRO | D33: KM 2 VIA FUNZA SIBERIA – PARQUE INDUSTRIAL EL TREBOL | F33: 3505916780 | G33: Asering SAS | Asering S.A.S | H33: comercialaseringsas.co | I33: A00000003 | J33: HIPOCLORITO DE SODIO LIQUIDO_TAMBOR X 250KG - 15% | K33: 1450 | L33: KG | M33: KG | N33: 250 | O33: 2 | P33: FURGON | Q33: 7 | R33: CONTADO | S33: 0
A34: P0005 | B34: ASERING SAS | C34: DANIELA CASTRO | D34: KM 2 VIA FUNZA SIBERIA – PARQUE INDUSTRIAL EL TREBOL | F34: 3505916780 | G34: Asering SAS | Asering S.A.S | H34: comercialaseringsas.co | I34: A00000004 | J34: HIPOCLORITO DE SODIO LIQUIDO_GARRAFA X 24KG - 15% | K34: 1507 | L34: KG | M34: KG | N34: 24 | O34: 2 | P34: FURGON | Q34: 7 | R34: CONTADO | S34: 0
A35: P0005 | B35: ASERING SAS | C35: DANIELA CASTRO | D35: KM 2 VIA FUNZA SIBERIA – PARQUE INDUSTRIAL EL TREBOL | F35: 3505916780 | G35: Asering SAS | Asering S.A.S | H35: comercialaseringsas.co | I35: A00000005 | J35: AGUA DESMINERALIZADA_GARRAFA X 20L | K35: 2100 | L35: L | M35: L | N35: 20 | O35: 2 | P35: FURGON | Q35: 7 | R35: CONTADO | S35: 0
A36: P0005 | B36: ASERING SAS | C36: DANIELA CASTRO | D36: KM 2 VIA FUNZA SIBERIA – PARQUE INDUSTRIAL EL TREBOL | F36: 3505916780 | G36: Asering SAS | Asering S.A.S | H36: comercialaseringsas.co | I36: A00000011 | J36: ACIDO CITRICO SOLIDO_BOLSA X 1KG - 99% | K36: 10084 | L36: KG | M36: KG | N36: 1 | O36: 2 | P36: FURGON | Q36: 7 | R36: CONTADO | S36: 0
A37: P0005 | B37: ASERING SAS | C37: DANIELA CASTRO | D37: KM 2 VIA FUNZA SIBERIA – PARQUE INDUSTRIAL EL TREBOL | F37: 3505916780 | G37: Asering SAS | Asering S.A.S | H37: comercialaseringsas.co | J37: ACIDO NITRICO_LIQUIDO X 25KG | K37: 2747 | L37: KG | M37: KG | N37: 25 | O37: 2 | P37: FURGON | Q37: 7 | R37: CONTADO | S37: 0
A38: P0006 | B38: MACRO QUIMICA LTDA | C38: MARTHA HURTADO | D38: CALLE 72 A N° 20 A - 15 3ER PSIO | E38: 6012178519 | H38: macroquimicaltda@hotmail.com | I38: A00000005 | J38: AGUA DESMINERALIZADA_GARRAFA X 20L | K38: =63000/20 -> 3150 | L38: L | M38: L | N38: 20 | O38: 5 | P38: FURGON | Q38: 30 | R38: CONTADO | S38: 0
A39: P0007 | B39: MAR QUIMICOS SAS | C39: MIGUEL RAMIREZ | D39: CR 69C N.31- 22 SUR – BARRIO CARVAJAL | E39: 6017437434 | F39: 3125920108 | H39: gerencia@mqrsas.com | I39: A00000006 | J39: SILICONA ANTIESPUMANTE LIQUIDO_GARRAFA X 20L | K39: =330000/20 -> 16500 | L39: L | M39: L | N39: 20 | O39: 5 | P39: FURGON | Q39: 7 | R39: CONTADO | S39: 0
A40: P0008 | B40: CASA QUIMICOS SAS | C40: CALLE 73 # 20-51 | D40: CALLE 73 # 20-51 | E40: 6015438885 | H40: VENTAS@CASAQUIMICOS.COM | I40: A00000009 | J40: POLIMERO ANIONICO SOLIDO_ASPRE FLOC AN 315_BOLSA X 1KG - 99% | K40: 23000 | L40: KG | M40: KG | N40: 1 | Q40: 7 | R40: CONTADO | S40: 0
...

Sheet TABLA_3_ALMACEN
A1: CODIGO | B1: ITEM | C1: CANTIDAD
A2: L00000001 | B2: Tuerca hexagonal 5/16" | C2: 137
A3: L00000002 | B3: Tuerca de acero inox 3/8" | C3: 86
A4: L00000003 | B4: Tuerca de seguridad 1/4" | C4: 45
A5: L00000004 | B5: Tuerca de seguridad zincada 3/8" | C5: 60
A6: L00000005 | B6: Tuerca mariposa 3/8" | C6: 65
A7: L00000006 | B7: Tuerca de acero inox 1 1/2" | C7: 88
A8: L00000007 | B8: Tuerca mariposa 1/4" | C8: 7
A9: L00000008 | B9: Tuerca mariposa 1/2" | C9: 3
A10: L00000009 | B10: Tornillo hexagonal 1/4" x 3/4" | C10: 19
A11: L00000010 | B11: Tornillo cabeza redonda 1/4" | C11: 16
A12: L00000011 | B12: Tornillo hexagonal 3/8" x 1 1/4" | C12: 18
A13: L00000012 | B13: Tornillo cabeza de gota 1/4" x 1/2" | C13: 61
... A19: L00000018 | B19: Chazo expansivo de acero 3/8" | C19: 14
A20: L00000019 | B20: Tornillo roscado 5/16" x 3/4" | C20: =160-23 -> 137
A21: L00000020 | B21: Tornillo roscado 1/2" x 1 1/2" | C21: 183
A22: L00000021 | B22: Tornillo expansivo roscado 1/2" x 2 1/2" | C22: 64
A23: L00000022 | B23: Tornillo roscado 1/2" x 2" | C23: 42
A24: L00000023 | B24: Tornillo expansivo roscado 1/2" x 2" | C24: 32
A25: L00000024 | B25: Tornillo expansivo roscado 1/2" x 3" | C25: 29
A26: L00000025 | B26: Tornillo roscado 9/16" x 2" | C26: 32
A27: L00000026 | B27: Tornillo hexagonal de rosca 1/2" x 5" | C27: 3
A28: L00000027 | B28: Tornillo hexagonal de rosca 1/4" x 4" | C28: 11
A29: L00000028 | B29: Tornillo expansivo roscado 3/8" x 2 1/2" | C29: 7
A30: L00000029 | B30: Tornillo expansivo roscado 3/8" x 3" | C30: 4
A31: L00000030 | B31: Tornillo roscado 1/2" x 2 1/2" | C31: 10
A32: L00000031 | B32: Tornillo expansivo 5/16" x 5" | C32: 16
... A42: L00000041 | B42: Tornillo de acero 9/16" x 1 1/4" | C42: 14
A43: L00000042 | B43: Tuerca de acero 5/8" | C43: =238+24 -> 262
A44: L00000043 | B44: Tuerca de seguridad 1/2" | C44: 131
A45: L00000044 | B45: Chazo expansivo de acero 1/2" x 2" | C45: 1
A46: L00000045 | B46: Chazo expansivo de acero 3/8" | C46: 1
A47: L00000046 | B47: Chazo expansivo de acero 1/4" x 1" | C47: 18
A48: L00000047 | B48: Chazo expansivo de acero 5/16" x 2" | C48: 1
A49: L00000048 | B49: Chazo expansivo de acero 5/16" x 1 1/2" | C49: 2
A50: L00000049 | B50: Chazo expansivo de acero 1/4" x 1 1/2" | C50: 2
A51: L00000050 | B51: Chazo expansivo de acero 1/2" x 4/2" | C51: 9
A52: L00000051 | B52: Tuerca de acero inoxidable 3/4" | C52: 30
A53: L00000052 | B53: Tuerca de acero inoxidable 9/16" | C53: 38
A54: L00000053 | B54: Tornillo de acero inoxidable 5/16" x 2 3/4" | C54: 9
...

Sheet TABLA_4_BODEGA
A1: UBICACIÓN | B1: NIVEL | C1: POSICION | D1: LOCALIZADOR | E1: CODIGO | F1: DESCRIPCION | G1: CANTIDAD | H1: UNIDAD
A2: 1 | B2: 3 | C2: 1 | D2: R1N3P3 | E2: A00000050 | F2: FRASCO AMBAR DE MX LABORATORIO PLASTICO 250 ml | G2: =35+26 -> 61 | H2: UND
A3: 1 | B3: 3 | C3: 1 | D3: R1N3P3 | E3: A00000051 | F3: FRASCO AMBAR DE MX LABORATORIO VIDRIO 250 ml | G3: =56+68 -> 124 | H3: UND
A4: 1 | B4: 3 | C4: 2 | D4: R1N3P3 | E4: A00000052 | F4: CEPILLO DE CERDA GRUESA - VERDE | G4: 2 | H4: UND
A5: 1 | B5: 3 | C5: 2 | D5: R1N3P3 | E5: A00000053 | F5: QUITA TELARAÑAS | G5: 1 | H5: UND
A6: 1 | B6: 3 | C6: 2 | D6: R1N3P3 | E6: A00000054 | F6: ANGEO DE PISCINA | G6: 1 | H6: UND
A7: 1 | B7: 3 | C7: 3 | D7: R1N3P3 | E7: A00000055 | F7: POLAINAS DE CARNAZA | G7: 1 | H7: UND
A8: 1 | B8: 3 | C8: 3 | D8: R1N3P3 | E8: A00000056 | F8: PETO DE CARNAZA | G8: 1 | H8: UND
A9: 1 | B9: 3 | C9: 3 | D9: R1N3P3 | E9: A00000057 | F9: POLAINAS DEPORTIVA | G9: 1 | H9: UND
A10: 1 | B10: 3 | C10: 3 | D10: R1N3P3 | E10: A00000058 | F10: CARETA DE PROTECCION PODA | G10: 1 | H10: UND
A11: 1 | B11: 3 | C11: 4 | D11: R1N3P3 | E11: A00000059 | F11: NILON PARA GUADAÑA | G11: 20 | H11: M
A12: 1 | B12: 3 | C12: 5 | D12: R1N3P3 | E12: A00000060 | F12: HERRAMIENTA DE GUADAÑA | G12: 1 | H12: UND
A13: 1 | B13: 3 | C13: 5 | D13: R1N3P3 | E13: A00000061 | F13: CUCHILLA DE TRES PUNTAS | G13: 1 | H13: UND
A14: 1 | B14: 3 | C14: 5 | D14: R1N3P3 | E14: A00000062 | F14: CUCHILLA PLANA | G14: 2 | H14: UND
A15: 1 | B15: 3 | C15: 5 | D15: R1N3P3 | E15: A00000063 | F15: TIJERAS DE JARDINERIA | G15: 2 | H15: UND
... A32: 1 | B32: 2 | C32: 6 | D32: R1N2P2 | E32: A00000080 | F32: SUPER TRAMP - PEGANTE LIQUIDO ATRAPA MOSCAS | G32: 350 | H32: GR
A33: 1 | B33: 2 | C33: 6 | D33: R1N2P2 | E33: A00000081 | F33: EXTERMIN INSECTICIDA LIQUIDO | G33: 440
A34: 1 | B34: 2 | C34: 6 | D34: R1N2P2 | E34: A00000082 | F34: RAID PASTILLAS | G34: 67 | H34: UND
A35: 1 | B35: 2 | C35: 6 | D35: R1N2P2 | E35: A00000083 | F35: GRANULOS PARA ESPARCIR AGITA | G35: 2 | H35: UND
A36: 1 | B36: 2 | C36: 7 | D36: R1N2P2 | E36: A00000084 | F36: FWD CONTROL - BACTERIAS ESPECIFICAS PARA POZOS SEPTICOS | G36: 100 | H36: GR
A37: 1 | B37: 2 | C37: 2 | D37: R1N2P2 | E37: A00000085 | F37: GLYFOSA_HERBICIDA AGRICOLA | G37: 10 | H37: GR
A38: 1 | B38: 2 | C38: 3 | D38: R1N2P3 | E38: A00000086 | F38: NAIROBI INSECTICIDA AGRICOLA | G38: 800 | H38: ML
A39: 1 | B39: 2 | C39: 3 | D39: R1N2P3 | E39: A00000087 | F39: ROUNDUP ACTIVO_HERBICIDA AGRICOLA | G39: 0 | H39: ML
A40: 1 | B40: 2 | C40: 5 | D40: R1N2P5 | E40: A00000088 | F40: BABOXA SE_MOLUSQUICIDA AGRICOLA | G40: 700 | H40: GR
A41: 1 | B41: 2 | C41: 7 | D41: R1N2P7 | E41: A00000089 | F41: CORBOX COMPOX_ABONO ORGANICO | G41: 0 | H41: KG
A42: 1 | B42: 2 | C42: 11 | D42: R1N2P7 | E42: A00000090 | F42: BISULFITO DE SODIO 99% | G42: 20 | H42: KG
A43: 1 | B43: 1 | C43: 1 | D43: R1N1P1 | E43: A00000091 | F43: PEROXIDO DE HIDROGENO 50% | G43: 33 | H43: KG
A44: 1 | B44: 1 | C44: 2 | D44: R1N1P2 | E44: A00000092 | F44: SILICONA ANTIESPUMANTE | G44: 28 | H44: L
A45: 1 | B45: 1 | C45: 3 | D45: R1N1P2 | E45: A00000093 | F45: ACIDO CITRICO | G45: 75 | H45: KG
... A132: 5 | B132: 1 | C132: 1 | D132: R5N1P1 | E132: A00000179 | F132: HIDROLAVADORA | G132: 1 | H132: UND

Sheet TABLA_5_CLIENTES
A1: CODIGO | B1: CLIENTE | C1: RAZON SOCIAL | D1: TELEFONO 1 | E1: TELEFONO 2 | F1: CONTACTO | G1: CORREO | H1: CIUDAD | I1: TIPO DE AGUA | J1: CANTIDAD PROMEDIO KG
A2: C00000001 | B2: PARQUE INDUSTRIAL LOGIKA MADRID-PACTIA S.A.S | C2: PACTIA SAS | D2: 3148487797 | F2: JUAN CARLOS GUALTEROS | G2: jgualtero@pactia.com | H2: MADRID | I2: POZO SEPTICO | J2: 24000
A3: C00000002 | B3: YANBAL TENJO/YANBAL DE COLOMBIA S.A.S | C3: YANBAL DE COLOMBIA S.A.S. en adelante “YANBAL” | D3: 3102552243 | E3: 3202111359 | F3: KATHERINE ALBARRACIN - LISETH BARAHONA | G3: Katherine.Albarracin@yanbal.com - Liseth Barahona<Liseth.Barahona@yanbal.com | H3: TENJO | I3: ARnD <20% | J3: 20000
A4: C00000003 | B4: UNIVERSIDAD EL BOSQUE | C4: UNIVERSIDAD EL BOSQUE | D4: 3132119704 | F4: JHON MILLAN | G4: millanalexander@unbosque.edu.co | H4: BOGOTA | I4: POZO SEPTICO | J4: 50000
A5: C00000004 | B5: BETANIA COLOMBIA S.A.S/PARQUE INDUSTRIAL SAN CARLOS V | C5: BETANIA DE COLOMBIA S.A.S | D5: 3113678086 | F5: SONIA FRANCO | G5: sfranco@agrobetania.com.co | H5: FUNZA | I5: POZO SEPTICO | J5: 30000
A6: C00000005 | B6: ECOSERVICIOS | C6: ECOSERVICIOS DE OCCIDENTE S.A.S E.S.P | D6: 3185166793 | F6: TATIANA DUEÑAS | G6: comercial2@ecoserviciosdeoccidente.com | H6: EL ROSAL | I6: POZO SEPTICO | J6: 70000

Sheet TABLA_6_PRODUCTO TERMINADO
A1: NOMBRE PRODUCTO TERMINADO | B1: Aguas con carga muy baja
A2: PT1 | B2: TIPO I | E2: CANTIDAD A PRODUCIR | F2: 100000
B3: CODIGO DE LA MATERIA PRIMA | C3: NOMBRE DE LA MATERIA PRIMA | D3: CANTIDAD REQUERIDA X UND A PRODUCIR | E3: TOTAL REQUERIDO ORDEN DE PRODUCCION | F3: UNIDAD DE CONSUMO | G3: UNIDAD DE COMPRA | H3: PRECIO DE COMPRA | I3: COSTO
B4: A00000001 | C4: SODA EN ESCAMAS | D4: 0 | E4: =+D4*$F$2 -> 0 | F4: KG | G4: KG | H4: 4400 | I4: =+H4*E4 -> 0
B5: A00000007 | C5: CLORURO FERRICO | D5: 0.00023809524 | E5: =+D5*$F$2 -> 23.809524 | F5: KG | G5: KG | H5: 3333 | I5: =+H5*E5 -> 79357.143
B6: A00000009 | C6: PAM ANIONICO | D6: 9.0909091e-06 | E6: =+D6*$F$2 -> 0.90909091 | F6: KG | G6: KG | H6: 23000 | I6: =+H6*E6 -> 20909.091
B7: A00000003 | C7: HIPOCLORITO DE SODIO | D7: 0 | E7: =+D7*$F$2 -> 0 | F7: KG | G7: KG | H7: 1446 | I7: =+H7*E7 -> 0
A10: PT2 | B10: TIPO II | E10: CANTIDAD A PRODUCIR | F10: 100000
B11: CODIGO DE LA MATERIA PRIMA | C11: NOMBRE DE LA MATERIA PRIMA | D11: CANTIDAD REQUERIDA X UND A PRODUCIR | E11: TOTAL REQUERIDO ORDEN DE PRODUCCION | F11: UNIDAD DE CONSUMO | G11: UNIDAD DE COMPRA | H11: PRECIO DE COMPRA | I11: COSTO
B12: A00000001 | C12: SODA EN ESCAMAS | D12: 0 | E12: =+D12*$F$2 -> 0 | F12: KG | G12: KG | H12: 4400 | I12: =+H12*E12 -> 0
B13: A00000007 | C13: CLORURO FERRICO | D13: 0.00023809524 | E13: =+D13*$F$2 -> 23.809524 | F13: KG | G13: KG | H13: 3333 | I13: =+H13*E13 -> 79357.143
B14: A00000009 | C14: PAM ANIONICO | D14: 9.0909091e-06 | E14: =+D14*$F$2 -> 0.90909091 | F14: KG | G14: KG | H14: 23000 | I14: =+H14*E14 -> 20909.091
B15: A00000003 | C15: HIPOCLORITO DE SODIO | D15: 0 | E15: =+D15*$F$2 -> 0 | F15: KG | G15: KG | H15: 1446 | I15: =+H15*E15 -> 0
A18: PT3 | B18: TIPO III | E18: CANTIDAD A PRODUCIR | F18: 100000
B19: CODIGO DE LA MATERIA PRIMA | C19: NOMBRE DE LA MATERIA PRIMA | D19: CANTIDAD REQUERIDA X UND A PRODUCIR | E19: TOTAL REQUERIDO ORDEN DE PRODUCCION | F19: UNIDAD DE CONSUMO | G19: UNIDAD DE COMPRA | H19: PRECIO DE COMPRA | I19: COSTO
B20: A00000001 | C20: SODA EN ESCAMAS | D20: 0 | E20: =+D20*$F$2 -> 0 | F20: KG | G20: KG | H20: 4400 | I20: =+H20*E20 -> 0
B21: A00000007 | C21: CLORURO FERRICO | D21: 0.00023809524 | E21: =+D21*$F$2 -> 23.809524 | F21: KG | G21: KG | H21: 3333 | I21: =+H21*E21 -> 79357.143
B22: A00000009 | C22: PAM ANIONICO | D22: 9.0909091e-06 | E22: =+D22*$F$2 -> 0.90909091 | F22: KG | G22: KG | H22: 23000 | I22: =+H22*E22 -> 20909.091
B23: A00000003 | C23: HIPOCLORITO DE SODIO | D23: 0 | E23: =+D23*$F$2 -> 0 | F23: KG | G23: KG | H23: 1446 | I23: =+H23*E23 -> 0
A26: PT4 | B26: TIPO IV | E26: CANTIDAD A PRODUCIR | F26: 100000
B27: CODIGO DE LA MATERIA PRIMA | C27: NOMBRE DE LA MATERIA PRIMA | D27: CANTIDAD REQUERIDA X UND A PRODUCIR | E27: TOTAL REQUERIDO ORDEN DE PRODUCCION | F27: UNIDAD DE CONSUMO | G27: UNIDAD DE COMPRA | H27: PRECIO DE COMPRA | I27: COSTO
B28: A00000001 | C28: SODA EN ESCAMAS | D28: 0 | E28: =+D28*$F$2 -> 0 | F28: KG | G28: KG | H28: 4400 | I28: =+H28*E28 -> 0
B29: A00000007 | C29: CLORURO FERRICO | D29: 0.00023809524 | E29: =+D29*$F$2 -> 23.809524 | F29: KG | G29: KG | H29: 3333 | I29: =+H29*E29 -> 79357.143
B30: A00000009 | C30: PAM ANIONICO | D30: 9.0909091e-06 | E30: =+D30*$F$2 -> 0.90909091 | F30: KG | G30: KG | H30: 23000 | I30: =+H30*E30 -> 20909.091
B31: A00000003 | C31: HIPOCLORITO DE SODIO | D31: 0 | E31: =+D31*$F$2 -> 0 | F31: KG | G31: KG | H31: 1446 | I31: =+H31*E31 -> 0

Sheet TABLA_7_MANO DE OBRA
A1: ITEM | B1: CARGO | C1: BASE | D1: EMPLEADOR | E1: % OPERACIÓN MOD | F1: % OPERACIÓN MOI | G1: TIPO | H1: SALARIO % MOD | I1: SALARIO % MOI
A2: 1 | B2: GERENTE DE OPERACIONES | C2: 6500000 | D2: =+C2*1.49 -> 9685000 | E2: 0 | F2: 1 | G2: MOI | H2: =+D2*E2 -> 0 | I2: =+D2*F2 -> 9685000
A3: 2 | B3: DIRECTOR ADMINISTRATIVO | C3: =2520000+186667 -> 2706667 | D3: =+C3*1.49 -> 4032933.8 | E3: 0 | F3: 1 | G3: MOI | H3: =+D3*E3 -> 0 | I3: =+D3*F3 -> 4032933.8
A4: 3 | B4: COORDINADOR DE MTTO | C4: 2125000 | D4: =+C4*1.49 -> 3166250 | E4: 0.5 | F4: 0.5 | G4: MOD | H4: =+D4*E4 -> 1583125 | I4: =+D4*F4 -> 1583125
A5: 4 | B5: TECNICO DE LABORATORIO | C5: 1575000 | D5: =+C5*1.49 -> 2346750 | E5: 0.5 | F5: 0.5 | G5: MOD | H5: =+D5*E5 -> 1173375 | I5: =+D5*F5 -> 1173375
A6: 5 | B6: ANALSITA HSEQ | C6: 1575000 | D6: =+C6*1.49 -> 2346750 | E6: 0 | F6: 1 | G6: MOI | H6: =+D6*E6 -> 0 | I6: =+D6*F6 -> 2346750
A7: 6 | B7: AUXILIAR DE OPERACIONES | C7: 1623500 | D7: =+C7*1.49 -> 2419015 | E7: 1 | F7: 0 | G7: MOD | H7: =+D7*E7 -> 2419015 | I7: =+D7*F7 -> 0
A8: 7 | B8: SERVICIO DE VIGILANCIA | C8: 3000000 | D8: =+C8*1.49 -> 4470000 | E8: 0 | F8: 1 | G8: MOI | H8: =+D8*E8 -> 0 | I8: =+D8*F8 -> 4470000
B9: TOTAL | C9: =SUM(C2:C8) -> 19105167 | D9: =SUM(D2:D8) -> 28466699 | H9: =SUM(H2:H8) -> 5175515 | I9: =SUM(I2:I8) -> 23291184
H10: =+H9/H11 -> 0.66608945 | I10: =+I9/H11 -> 2.9975784 | J10: HM/L
H11: =31080000*25% -> 7770000
H12: =+H9/176 -> 29406.335 | I12: =+I9/176 -> 132336.27 | J12: HM/H

Sheet TABLA_8_DEPRECIACION EQUIPOS 
A1: ITEM | B1: CODIGO | C1: EQUIPO | D1: FECHA COMPRA | E1: COSTO ($) | F1: VIDA UTIL (AÑOS) | G1: % Valor residual | H1: VALOR RESIDUAL | I1: DEPRESIACION ANUAL | J1: años usados | K1: DEPRESIACION ACUMULADA | L1: VALOR ACTUAL
A2: 1 | B2: 117 | C2: TABLERO DE FUERZA | D2: 43313 | E2: 135375000 | F2: 10 | G2: 0.05 | H2: =+E2*G2 -> 6768750 | I2: =+(E2-H2)/F2 -> 12860625 | J2: =(TODAY()-D2)/365 -> 7.4356164 | K2: =+I2*J2 -> 95626675 | L2: =+E2-K2 -> 39748325
A3: 2 | B3: 118 | C3: TABLERO DE CONTROL | D3: 43313 | E3: 72200000 | F3: 10 | G3: 0.05 | H3: =+E3*G3 -> 3610000 | I3: =+(E3-H3)/F3 -> 6859000 | J3: =(TODAY()-D3)/365 -> 7.4356164 | K3: =+I3*J3 -> 51000893 | L3: =+E3-K3 -> 21199107
A4: 3 | B4: 119 | C4: MEDIDOR DE FLIJO | D4: 43313 | E4: 7877922.5 | F4: 8 | G4: 0 | H4: =+E4*G4 -> 0 | I4: =+(E4-H4)/F4 -> 984740.31 | J4: =(TODAY()-D4)/365 -> 7.4356164 | K4: =+I4*J4 -> 7322151.3 | L4: =+E4-K4 -> 555771.24
A5: 4 | B5: 122 | C5: MEZCLADOR ESTATICO | D5: 43313 | E5: 27380045 | F5: 10 | G5: 0.1 | H5: =+E5*G5 -> 2738004.5 | I5: =+(E5-H5)/F5 -> 2464204 | J5: =(TODAY()-D5)/365 -> 7.4356164 | K5: =+I5*J5 -> 18322876 | L5: =+E5-K5 -> 9057168.9
A6: 5 | B6: 120 | C6: BOMBA DOSIFICADORA | D6: 43313 | E6: 8460937.5 | F6: 10 | G6: 0.1 | H6: =+E6*G6 -> 846093.75 | I6: =+(E6-H6)/F6 -> 761484.38 | J6: =(TODAY()-D6)/365 -> 7.4356164 | K6: =+I6*J6 -> 5662105.7 | L6: =+E6-K6 -> 2798831.8
A7: 6 | B7: 121 | C7: BOMBA DOSIFICADORA | D7: 43313 | E7: 8460937.5 | F7: 10 | G7: 0.1 | H7: =+E7*G7 -> 846093.75 | I7: =+(E7-H7)/F7 -> 761484.38 | J7: =(TODAY()-D7)/365 -> 7.4356164 | K7: =+I7*J7 -> 5662105.7 | L7: =+E7-K7 -> 2798831.8
A8: 7 | B8: 123 | C8: DAF EDUR | D8: 43313 | E8: 5.0823656e+08 | F8: 20 | G8: 0.1 | H8: =+E8*G8 -> 50823656 | I8: =+(E8-H8)/F8 -> 22870645 | J8: =(TODAY()-D8)/365 -> 7.4356164 | K8: =+I8*J8 -> 1.7005734e+08 | L8: =+E8-K8 -> 3.3817921e+08
A9: 8 | B9: 124 | C9: TANQUE DE SATRACION DAFF | D9: 43313 | E9: 304942115 | F9: 20 | G9: 0.1 | H9: =+E9*G9 -> 30494212 | I9: =+(E9-H9)/F9 -> 13722395 | J9: =(TODAY()-D9)/365 -> 7.4356164 | K9: =+I9*J9 -> 1.0203447e+08 | L9: =+E9-K9 -> 2.0290765e+08
A10: 9 | B10: 125 | C10: VALVULA ACTUADORA PROPORCIONAL | D10: 43313 | E10: 14671942 | F10: 8 | G10: 0 | H10: =+E10*G10 -> 0 | I10: =+(E10-H10)/F10 -> 1833992.8 | J10: =(TODAY()-D10)/365 -> 7.4356164 | K10: =+I10*J10 -> 13636867 | L10: =+E10-K10 -> 1035075.4
A11: 10 | B11: 126 | C11: BOMBA MULTIETAPA DAF | D11: 43313 | E11: 12815500 | F11: 10 | G11: 0.1 | H11: =+E11*G11 -> 1281550 | I11: =+(E11-H11)/F11 -> 1153395 | J11: =(TODAY()-D11)/365 -> 7.4356164 | K11: =+I11*J11 -> 8576202.8 | L11: =+E11-K11 -> 4239297.2
A12: 11 | B12: 127 | C12: SENSOR DE PRESION | D12: 43313 | E12: 5860835 | F12: 8 | G12: 0 | H12: =+E12*G12 -> 0 | I12: =+(E12-H12)/F12 -> 732604.38 | J12: =(TODAY()-D12)/365 -> 7.4356164 | K12: =+I12*J12 -> 5447365.1 | L12: =+E12-K12 -> 413469.87
A13: 12 | B13: 128 | C13: SENSOR DE PRESION | D13: 43313 | E13: 5860835 | F13: 8 | G13: 0 | H13: =+E13*G13 -> 0 | I13: =+(E13-H13)/F13 -> 732604.38 | J13: =(TODAY()-D13)/365 -> 7.4356164 | K13: =+I13*J13 -> 5447365.1 | L13: =+E13-K13 -> 413469.87
... A100: 99 | B100: 255 | C100: SISTEMA DESHIDRATADOR DE LODOS | D100: 43313 | E100: 72200000 | F100: 10 | G100: 0.1 | H100: =+E100*G100 -> 7220000 | I100: =+(E100-H100)/F100 -> 6498000 | J100: =(TODAY()-D100)/365 -> 7.4356164 | K100: =+I100*J100 -> 48316636 | L100: =+E100-K100 -> 23883364
A101: 100 | B101: 253 | C101: SISTEMA DESHIDRATADOR DE LODOS - MOTOR 1 IZQUIERDO | D101: 43313 | F101: 8 | G101: 0.1 | H101: =+E101*G101 -> 0 | I101: =+(E101-H101)/F101 -> 0 | J101: =(TODAY()-D101)/365 -> 7.4356164 | K101: =+I101*J101 -> 0 | L101: =+E101-K101 -> 0
A102: 101 | B102: 254 | C102: SISTEMA DESHIDRATADOR DE LODOS - MOTOR 2 DERECHO | D102: 43313 | F102: 8 | G102: 0.1 | H102: =+E102*G102 -> 0 | I102: =+(E102-H102)/F102 -> 0 | J102: =(TODAY()-D102)/365 -> 7.4356164 | K102: =+I102*J102 -> 0 | L102: =+E102-K102 -> 0
A103: 102 | B103: 256 | C103: MOTOR TOLVA | D103: 43313 | F103: 8 | G103: 0.1 | H103: =+E103*G103 -> 0 | I103: =+(E103-H103)/F103 -> 0 | J103: =(TODAY()-D103)/365 -> 7.4356164 | K103: =+I103*J103 -> 0 | L103: =+E103-K103 -> 0
A104: 103 | B104: 257 | C104: TOLVA | D104: 43313 | F104: 20 | G104: 0.1 | H104: =+E104*G104 -> 0 | I104: =+(E104-H104)/F104 -> 0 | J104: =(TODAY()-D104)/365 -> 7.4356164 | K104: =+I104*J104 -> 0 | L104: =+E104-K104 -> 0
A105: 104 | B105: 266 | C105: TABLERO FUERZA Y CONTROL DESIDRATADOR DE LODOS TOLVA | D105: 43313 | F105: 10 | G105: 0.05 | H105: =+E105*G105 -> 0 | I105: =+(E105-H105)/F105 -> 0 | J105: =(TODAY()-D105)/365 -> 7.4356164 | K105: =+I105*J105 -> 0 | L105: =+E105-K105 -> 0
A106: 105 | B106: 258 | C106: BOMBA DOSIFICADORA DE SODA CAUSTICA | D106: 43313 | E106: 3489065 | F106: 10 | G106: 0.1 | H106: =+E106*G106 -> 348906.5 | I106: =+(E106-H106)/F106 -> 314015.85 | J106: =(TODAY()-D106)/365 -> 7.4356164 | K106: =+I106*J106 -> 2334901.4 | L106: =+E106-K106 -> 1154163.6
A107: 106 | B107: 260 | C107: BOMBA DE DAFRAGMA | D107: 43313 | E107: 1164225 | F107: 10 | G107: 0.1 | H107: =+E107*G107 -> 116422.5 | I107: =+(E107-H107)/F107 -> 104780.25 | J107: =(TODAY()-D107)/365 -> 7.4356164 | K107: =+I107*J107 -> 779105.75 | L107: =+E107-K107 -> 385119.25
A108: 107 | B108: 259 | C108: SISTEMA DE PREPARACION DE QUIMICOS - TANQUE | D108: 43313 | E108: 126350000 | F108: 20 | G108: 0.1 | H108: =+E108*G108 -> 12635000 | I108: =+(E108-H108)/F108 -> 5685750 | J108: =(TODAY()-D108)/365 -> 7.4356164 | K108: =+I108*J108 -> 42277056 | L108: =+E108-K108 -> 84072944
A109: 108 | B109: 261 | C109: SISTEMA DE PREPARACION DE QUIMICOS - MOTOREDUCTOR 1 | D109: 43313 | F109: 8 | G109: 0.1 | H109: =+E109*G109 -> 0 | I109: =+(E109-H109)/F109 -> 0 | J109: =(TODAY()-D109)/365 -> 7.4356164 | K109: =+I109*J109 -> 0 | L109: =+E109-K109 -> 0
A110: 109 | B110: 262 | C110: SISTEMA DE PREPARACION DE QUIMICOS - MOTOREDUCTOR 2 | D110: 43313 | F110: 8 | G110: 0.1 | H110: =+E110*G110 -> 0 | I110: =+(E110-H110)/F110 -> 0 | J110: =(TODAY()-D110)/365 -> 7.4356164 | K110: =+I110*J110 -> 0 | L110: =+E110-K110 -> 0
A111: 110 | B111: 263 | C111: SISTEMA DE PREPARACION DE QUIMICOS - MOTOREDUCTOR 3 | D111: 43313 | F111: 8 | G111: 0.1 | H111: =+E111*G111 -> 0 | I111: =+(E111-H111)/F111 -> 0 | J111: =(TODAY()-D111)/365 -> 7.4356164 | K111: =+I111*J111 -> 0 | L111: =+E111-K111 -> 0
A112: 111 | B112: 264 | C112: SISTEMA DE PREPARACION DE QUIMICOS - MOTOREDUCTOR 4 | D112: 43313 | F112: 8 | G112: 0.1 | H112: =+E112*G112 -> 0 | I112: =+(E112-H112)/F112 -> 0 | J112: =(TODAY()-D112)/365 -> 7.4356164 | K112: =+I112*J112 -> 0 | L112: =+E112-K112 -> 0
A113: 112 | B113: 265 | C113: TEBLERO FUERZA Y CONTROL, SISTEMA DE PREPARACION DE QUIMICOS | D113: 43313 | F113: 10 | G113: 0.1 | H113: =+E113*G113 -> 0 | I113: =+(E113-H113)/F113 -> 0 | J113: =(TODAY()-D113)/365 -> 7.4356164 | K113: =+I113*J113 -> 0 | L113: =+E113-K113 -> 0
A114: 113 | B114: 267 | C114: MOTOR REDUCTOR BARRE LODOS DAF | D114: 43313 | E114: 3158750 | F114: 8 | G114: 0.1 | H114: =+E114*G114 -> 315875 | I114: =+(E114-H114)/F114 -> 355359.38 | J114: =(TODAY()-D114)/365 -> 7.4356164 | K114: =+I114*J114 -> 2642316 | L114: =+E114-K114 -> 516433.99
A115: 114 | B115: 268 | C115: TANQUE DE AGUAS LLUVIAS No. 1 | D115: 43313 | E115: 4963750 | F115: 20 | G115: 0.1 | H115: =+E115*G115 -> 496375 | I115: =+(E115-H115)/F115 -> 223368.75 | J115: =(TODAY()-D115)/365 -> 7.4356164 | K115: =+I115*J115 -> 1660884.3 | L115: =+E115-K115 -> 3302865.7
A116: 115 | B116: 269 | C116: TANQUE DE AGUASLLUVIAS No. 2 | D116: 43313 | E116: 4963750 | F116: 20 | G116: 0.1 | H116: =+E116*G116 -> 496375 | I116: =+(E116-H116)/F116 -> 223368.75 | J116: =(TODAY()-D116)/365 -> 7.4356164 | K116: =+I116*J116 -> 1660884.3 | L116: =+E116-K116 -> 3302865.7
A117: 116 | B117: 270 | C117: DOSIFICADORA VERTIMIENTO | D117: 43313 | E117: 961100.23 | F117: 8 | G117: 0.1 | H117: =+E117*G117 -> 96110.023 | I117: =+(E117-H117)/F117 -> 108123.78 | J117: =(TODAY()-D117)/365 -> 7.4356164 | K117: =+I117*J117 -> 803966.92 | L117: =+E117-K117 -> 157133.3
A118: 117 | B118: 275 | C118: BOMBA SUMERGIBLE DE LODOS | D118: 43313 | E118: 3158750 | F118: 10 | G118: 0.1 | H118: =+E118*G118 -> 315875 | I118: =+(E118-H118)/F118 -> 284287.5 | J118: =(TODAY()-D118)/365 -> 7.4356164 | K118: =+I118*J118 -> 2113852.8 | L118: =+E118-K118 -> 1044897.2
A119: 118 | C119: BOMBA DE CAUDAL | D119: 43313 | E119: 7039500 | F119: 10 | G119: 0.1 | H119: =+E119*G119 -> 703950 | I119: =+(E119-H119)/F119 -> 633555 | J119: =(TODAY()-D119)/365 -> 7.4356164 | K119: =+I119*J119 -> 4710872 | L119: =+E119-K119 -> 2328628
A120: 119 | B120: 271 | C120: BOMBA DE CAUDAL | D120: 43313 | E120: 7039500 | F120: 10 | G120: 0.1 | H120: =+E120*G120 -> 703950 | I120: =+(E120-H120)/F120 -> 633555 | J120: =(TODAY()-D120)/365 -> 7.4356164 | K120: =+I120*J120 -> 4710872 | L120: =+E120-K120 -> 2328628
A121: 120 | B121: 272 | C121: BOMBA DE CAUDAL | D121: 43313 | E121: 7039500 | F121: 10 | G121: 0.1 | H121: =+E121*G121 -> 703950 | I121: =+(E121-H121)/F121 -> 633555 | J121: =(TODAY()-D121)/365 -> 7.4356164 | K121: =+I121*J121 -> 4710872 | L121: =+E121-K121 -> 2328628
A122: 121 | B122: 273 | C122: TABLERO DE CONTROL | D122: 43313 | E122: 2707500 | F122: 10 | G122: 0.05 | H122: =+E122*G122 -> 135375 | I122: =+(E122-H122)/F122 -> 257212.5 | J122: =(TODAY()-D122)/365 -> 7.4356164 | K122: =+I122*J122 -> 1912533.5 | L122: =+E122-K122 -> 794966.51
A123: 122 | B123: 274 | C123: TOTALIZADOR | D123: 43313 | E123: 1805000 | F123: 8 | G123: 0.05 | H123: =+E123*G123 -> 90250 | I123: =+(E123-H123)/F123 -> 214343.75 | J123: =(TODAY()-D123)/365 -> 7.4356164 | K123: =+I123*J123 -> 1593777.9 | L123: =+E123-K123 -> 211222.09
A124: 123 | B124: 276 | C124: SOPLADOR DESARENADOR | D124: 43313 | E124: 7220000 | F124: 8 | G124: 0.1 | H124: =+E124*G124 -> 722000 | I124: =+(E124-H124)/F124 -> 812250 | J124: =(TODAY()-D124)/365 -> 7.4356164 | K124: =+I124*J124 -> 6039579.5 | L124: =+E124-K124 -> 1180420.5
A125: 124 | B125: 277 | C125: TABLERO ELECTRICO | D125: 43313 | E125: 1805000 | F125: 10 | G125: 0.05 | H125: =+E125*G125 -> 90250 | I125: =+(E125-H125)/F125 -> 171475 | J125: =(TODAY()-D125)/365 -> 7.4356164 | K125: =+I125*J125 -> 1275022.3 | L125: =+E125-K125 -> 529977.67
A126: 125 | B126: 278 | C126: MEDIDOR DE FLUJO DE DESARENADOR | D126: 43313 | E126: 7877922.5 | F126: 8 | G126: 0 | H126: =+E126*G126 -> 0 | I126: =+(E126-H126)/F126 -> 984740.31 | J126: =(TODAY()-D126)/365 -> 7.4356164 | K126: =+I126*J126 -> 7322151.3 | L126: =+E126-K126 -> 555771.24
...

Sheet CALCULO_FCA
A1: PARAMETRO CLAVE | B1: mg/l | C1: RESULTADO | D1: =IF(C6<0.2,"Bajo-bajo (Tipo I)", IF(C6<0.4,"Bajo-medio (Tipo II)", IF(C6<0.6,"Medio-medio (Tipo III)", IF(C6<0.8,"Alto-medio (Tipo IV)","Alto-alto (Tipo V)")))) -> Bajo-bajo (Tipo I) | F1: Tipo | G1: Rango FCA | H1: Clasificación | I1: Descripción
A2: DQO | B2: 400 | C2: =IF(B2<500,0,IF(B2<=1499,0.25,IF(B2<=5000,0.5,IF(B2<=10000,0.75,1)))) -> 0 | F2: Tipo I | G2: 0.00 – <0.20 | H2: Bajo-bajo | I2: Aguas con carga muy baja —
A3: SST | B3: 100 | C3: =IF(B3<200,0,IF(B3<=999,0.25,IF(B3<=5000,0.5,IF(B3<=10000,0.75,1)))) -> 0 | F3: Tipo II | G3: 0.20 – <0.40 | H3: Bajo-medio | I3: Aguas con carga leve —
A4: TURBIDEZ | B4: 150 | C4: =IF(B4<10,0,IF(B4<=49,0.25,IF(B4<=150,0.5,IF(B4<=500,0.75,1)))) -> 0.5 | F4: Tipo III | G4: 0.40 – <0.60 | H4: Medio-medio | I4: Aguas con carga media —
A5: CONDUCTIVIDAD | B5: 1800 | C5: =IF(B5<100,0,IF(B5<=499,0.25,IF(B5<=1499,0.5,IF(B5<=5000,0.75,1)))) -> 0.75 | F5: Tipo IV | G5: 0.60 – <0.80 | H5: Alto-medio | I5: Aguas con carga elevada —
A6: FCA | C6: =0.4*C2 + 0.3*C3 + 0.2*C4 + 0.1*C5 -> 0.175 | F6: Tipo V | G6: ≥ 0.80 | H6: Alto-alto | I6: Aguas con carga muy alta —

Sheet FORMATO_ORDEN DE PRODUCCION
D2: FORMATO ORDEN DE PRODUCCION - UT PTARnD SABANA DE OCCIDENTE | I2: VERSIÓN: 01
I3: CÓDIGO: GO-FT-04
I4: VIGENCIA: 28/07/2025
B6: N ORDEN
B8: PROCESO: | C8: TRATAMIENTO DE AGUA RESIDUAL ARD Y ARND -
G9: Q a procesar | H9: 100000 | I9: litros
B10: CODIGO PT | C10: PT00001 | D10: TIPO I | G10: Q set | H10: 10 | I10: l/s
G11: T proceso | H11: =+(H9/H10)/3600 -> 2.7777778 | I11: horas
B13: CODIGO | C13: NOMBRE DEL PRODUCTO | D13: QTY (kg) | E13: CONSUMO (und) | F13: TOTAL RQ (kg) | G13: $ (kg) | H13: COSTO $ | I13: VIDA UTIL (litros)
B14: A00000001 | C14: =+VLOOKUP(B14,TABLA_1_INV!A1:K43,3,FALSE) -> SODA EN ESCAMAS | D14: 0 | E14: KG | F14: =+(D14*$H$9) -> 0 | G14: 4400 | H14: =+F14*G14 -> 0 | I14: 0
B15: A00000007 | C15: =+VLOOKUP(B15,TABLA_1_INV!A2:K44,3,FALSE) -> CLORURO FERRICO | D15: 0.00023809524 | E15: KG | F15: =+(D15*$H$9) -> 23.809524 | G15: 3333 | H15: =+F15*G15 -> 79357.143 | I15: 0
B16: A00000009 | C16: =+VLOOKUP(B16,TABLA_1_INV!A3:K45,3,FALSE) -> PAM ANIONICO | D16: 9.0909091e-06 | E16: KG | F16: =+(D16*$H$9) -> 0.90909091 | G16: 23000 | H16: =+F16*G16 -> 20909.091 | I16: 0
B17: A00000003 | C17: =+VLOOKUP(B17,TABLA_1_INV!A4:K46,3,FALSE) -> HIPOCLORITO DE SODIO | D17: 0 | E17: KG | F17: =+(D17*$H$9) -> 0 | G17: 1446 | H17: =+F17*G17 -> 0 | I17: 0
B20: A00000032 | C20: =+VLOOKUP(B20,TABLA_1_INV!A6:K48,3,FALSE) -> SOLUCION DE LIMPIEZA ELECTRODOS | D20: =1000/(31080000*6) -> 5.3625054e-06 | E20: KG | G20: 390 | H20: =+(D20*G20)*$H$9 -> 209.13771
B21: A00000033 | C21: =+VLOOKUP(B21,TABLA_1_INV!A7:K49,3,FALSE) -> GRAVA GRUESA | D21: =1000/(31080000*6) -> 5.3625054e-06 | E21: KG | G21: 390 | H21: =+(D21*G21)*$H$9 -> 209.13771
B22: A00000034 | C22: =+VLOOKUP(B22,TABLA_1_INV!A8:K50,3,FALSE) -> GRAVA MEDIA | D22: =1000/(31080000*6) -> 5.3625054e-06 | E22: KG | G22: 390 | H22: =+(D22*G22)*$H$9 -> 209.13771
B23: A00000035 | C23: =+VLOOKUP(B23,TABLA_1_INV!A9:K51,3,FALSE) -> GRAVA FINA | D23: =1000/(31080000*6) -> 5.3625054e-06 | E23: KG | G23: 370 | H23: =+(D23*G23)*$H$9 -> 198.4127
B24: A00000036 | C24: =+VLOOKUP(B24,TABLA_1_INV!A10:K52,3,FALSE) -> ARENA | D24: =350/(31080000*6) -> 1.8768769e-06 | E24: KG | G24: 980 | H24: =+(D24*G24)*$H$9 -> 183.93393
B25: A00000038 | C25: =+VLOOKUP(B25,TABLA_1_INV!A12:K54,3,FALSE) -> CARBON ACTIVADO | D25: =80/(31080000*6) -> 4.2900043e-07 | E25: KG | G25: =100000/10 -> 10000 | H25: =+(D25*G25)*$H$9 -> 429.00043
B26: A00000039 | C26: =+VLOOKUP(B26,TABLA_1_INV!A14:K55,3,FALSE) -> LAMINAS DE HIERRO | D26: =80/(31080000*12) -> 2.1450021e-07 | E26: KG | G26: =250000/10 -> 25000 | H26: =+(D26*G26)*$H$9 -> 536.25054
B27: A00000040 | C27: =+VLOOKUP(B27,TABLA_1_INV!A15:K56,3,FALSE) -> LAMINAS DE ACERO INOX | D27: =6/(31080000/2) -> 3.8610039e-07 | E27: UND/L | G27: =146000*6 -> 876000 | H27: =+(D27*G27)*$H$9 -> 33822.394
B28: A00000041 | C28: =+VLOOKUP(B28,TABLA_1_INV!A16:K57,3,FALSE) -> MANGAS DE UF | D28: =400/(31080000*60) -> 2.1450021e-07 | E28: UND/L | G28: =400*900 -> 360000 | H28: =+(D28*G28)*$H$9 -> 7722.0077
C30: EQUIPOS | D30: kW equipo | E30: kWh | F30: $ TOTAL
C31: BOMBA ENTRADA AGUA RESIDUAL | D31: =10*1.341 -> 13.41 | E31: =+D31*760.5 -> 10198.305 | F31: =+E31*$H$11 -> 28328.625 | H31: =+F31 -> 28328.625
C32: BOMBA DOSIFICADORA | D32: =40/1000 -> 0.04 | E32: =+D32*760.5 -> 30.42 | F32: =+E32*$H$11 -> 84.5 | H32: =+F32 -> 84.5
C33: BOMBA SATURACION DAF | D33: =10*1.341 -> 13.41 | E33: =+D33*760.5 -> 10198.305 | F33: =+E33*$H$11 -> 28328.625 | H33: =+F33 -> 28328.625
C34: BOMBA FILTRACION DISCOS + FILTROS MULTI | D34: 11 | E34: =+D34*760.5 -> 8365.5 | F34: =+E34*$H$11 -> 23237.5 | H34: =+F34 -> 23237.5
C35: BOMBA MF + UF | D35: 2.2 | E35: =+D35*760.5 -> 1673.1 | F35: =+E35*$H$11 -> 4647.5 | H35: =+F35 -> 4647.5
C36: BOMBA RETROLAVADO UF | D36: 5 | E36: =+D36*760.5 -> 3802.5 | F36: =+E36*$H$11 -> 10562.5 | H36: =+F36 -> 10562.5
C38: MANO DE OBRA | G38: =+'TABLA_7_MANO DE OBRA'!H10 -> 0.66608945 | H38: =+G38*H9 -> 66608.945
C39: CIF (COSTOS INDIRECTOS DE FABRICACION) | G39: =+TABLA_CIF!F9 -> 3.3012424 | H39: =+G39*H9 -> 330124.24
C41: TOTAL | H41: =SUM(H14:H40) -> 635708.09

Sheet TABLA_CIF
C1: 1 | D1: 0.75 | E1: 0.5 | F1: 0.25
C2: 31080000 | D2: =+C2*75% -> 23310000 | E2: =+C2*50% -> 15540000 | F2: =+C2*25% -> 7770000 | G2: L/MES
A3: MANO DE OBRA INDIRECTA | B3: =+'TABLA_7_MANO DE OBRA'!I9 -> 23291184 | C3: =+B3/$C$2 -> 0.74939459 | D3: =+B3/$D$2 -> 0.99919279 | E3: =+B3/$E$2 -> 1.4987892 | F3: =+B3/$F$2 -> 2.9975784 | G3: $/L
A4: LUBRICANTES Y GRASA | B4: 250000 | C4: =+B4/$C$2 -> 0.008043758 | D4: =+B4/$D$2 -> 0.010725011 | E4: =+B4/$E$2 -> 0.016087516 | F4: =+B4/$F$2 -> 0.032175032 | G4: $/L
A5: REACTIVOS DE LABORATORIO | B5: =5037880/4 -> 1259470 | C5: =+B5/$C$2 -> 0.040523488 | D5: =+B5/$D$2 -> 0.054031317 | E5: =+B5/$E$2 -> 0.081046976 | F5: =+B5/$F$2 -> 0.16209395 | G5: $/L
A6: EPP Y DOTACIÓN | B6: 300000 | C6: =+B6/$C$2 -> 0.0096525097 | D6: =+B6/$D$2 -> 0.012870013 | E6: =+B6/$E$2 -> 0.019305019 | F6: =+B6/$F$2 -> 0.038610039 | G6: $/L
A7: MATERIAL DE ASEO | B7: 150000 | C7: =+B7/$C$2 -> 0.0048262548 | D7: =+B7/$D$2 -> 0.0064350064 | E7: =+B7/$E$2 -> 0.0096525097 | F7: =+B7/$F$2 -> 0.019305019 | G7: $/L
A8: TORNILLERÍA Y PEQUEÑOS REPUESTOS | B8: 400000 | C8: =+B8/$C$2 -> 0.012870013 | D8: =+B8/$D$2 -> 0.017160017 | E8: =+B8/$E$2 -> 0.025740026 | F8: =+B8/$F$2 -> 0.051480051 | G8: $/L
A9: CIF | C9: =SUM(C3:C8) -> 0.82531061 | D9: =SUM(D3:D8) -> 1.1004141 | E9: =SUM(E3:E8) -> 1.6506212 | F9: =SUM(F3:F8) -> 3.3012424 | G9: $/L
